Traceback (most recent call last):
  File "/home/marco/.local/lib/python3.8/site-packages/gns3fy/gns3fy.py", line 141, in http_call
    _response.raise_for_status()
  File "/usr/lib/python3/dist-packages/requests/models.py", line 940, in raise_for_status
    raise HTTPError(http_error_msg, response=self)
requests.exceptions.HTTPError: 401 Client Error: Unauthorized for url: http://127.0.0.1:3080/v2/version

During handling of the above exception, another exception occurred:

Traceback (most recent call last):
  File "pruebasGNS3.py", line 34, in <module>
    main()
  File "pruebasGNS3.py", line 14, in main
    print(gns3_server.get_version())
  File "/home/marco/.local/lib/python3.8/site-packages/gns3fy/gns3fy.py", line 153, in get_version
    return self.http_call("get", url=f"{self.base_url}/version").json()
  File "/home/marco/.local/lib/python3.8/site-packages/gns3fy/gns3fy.py", line 144, in http_call
    f"{_response.json()['status']}: {_response.json()['message']}"
  File "/usr/lib/python3/dist-packages/requests/models.py", line 897, in json
    return complexjson.loads(self.text, **kwargs)
  File "/usr/lib/python3/dist-packages/simplejson/__init__.py", line 518, in loads
    return _default_decoder.decode(s)
  File "/usr/lib/python3/dist-packages/simplejson/decoder.py", line 370, in decode
    obj, end = self.raw_decode(s)
  File "/usr/lib/python3/dist-packages/simplejson/decoder.py", line 400, in raw_decode
    return self.scan_once(s, idx=_w(s, idx).end())
simplejson.errors.JSONDecodeError: Expecting value: line 1 column 1 (char 0)
